no change     /apps/pkg/anaconda3/2020.11/condabin/conda
no change     /apps/pkg/anaconda3/2020.11/bin/conda
no change     /apps/pkg/anaconda3/2020.11/bin/conda-env
no change     /apps/pkg/anaconda3/2020.11/bin/activate
no change     /apps/pkg/anaconda3/2020.11/bin/deactivate
no change     /apps/pkg/anaconda3/2020.11/etc/profile.d/conda.sh
no change     /apps/pkg/anaconda3/2020.11/etc/fish/conf.d/conda.fish
no change     /apps/pkg/anaconda3/2020.11/shell/condabin/Conda.psm1
no change     /apps/pkg/anaconda3/2020.11/shell/condabin/conda-hook.ps1
no change     /apps/pkg/anaconda3/2020.11/lib/python3.8/site-packages/xontrib/conda.xsh
no change     /apps/pkg/anaconda3/2020.11/etc/profile.d/conda.csh
no change     /users/dwils152/.bashrc
No action taken.

CommandNotFoundError: Your shell has not been properly configured to use 'conda activate'.
To initialize your shell, run

    $ conda init <SHELL_NAME>

Currently supported shells are:
  - bash
  - fish
  - tcsh
  - xonsh
  - zsh
  - powershell

See 'conda init --help' for more information and options.

IMPORTANT: You may need to close and restart your shell after running 'conda init'.


Traceback (most recent call last):
  File "/apps/pkg/anaconda3/2020.11/lib/python3.8/site-packages/sqlalchemy/engine/base.py", line 3250, in _wrap_pool_connect
    return fn()
  File "/apps/pkg/anaconda3/2020.11/lib/python3.8/site-packages/sqlalchemy/pool/base.py", line 310, in connect
    return _ConnectionFairy._checkout(self)
  File "/apps/pkg/anaconda3/2020.11/lib/python3.8/site-packages/sqlalchemy/pool/base.py", line 868, in _checkout
    fairy = _ConnectionRecord.checkout(pool)
  File "/apps/pkg/anaconda3/2020.11/lib/python3.8/site-packages/sqlalchemy/pool/base.py", line 476, in checkout
    rec = pool._do_get()
  File "/apps/pkg/anaconda3/2020.11/lib/python3.8/site-packages/sqlalchemy/pool/impl.py", line 146, in _do_get
    self._dec_overflow()
  File "/apps/pkg/anaconda3/2020.11/lib/python3.8/site-packages/sqlalchemy/util/langhelpers.py", line 70, in __exit__
    compat.raise_(
  File "/apps/pkg/anaconda3/2020.11/lib/python3.8/site-packages/sqlalchemy/util/compat.py", line 207, in raise_
    raise exception
  File "/apps/pkg/anaconda3/2020.11/lib/python3.8/site-packages/sqlalchemy/pool/impl.py", line 143, in _do_get
    return self._create_connection()
  File "/apps/pkg/anaconda3/2020.11/lib/python3.8/site-packages/sqlalchemy/pool/base.py", line 256, in _create_connection
    return _ConnectionRecord(self)
  File "/apps/pkg/anaconda3/2020.11/lib/python3.8/site-packages/sqlalchemy/pool/base.py", line 371, in __init__
    self.__connect()
  File "/apps/pkg/anaconda3/2020.11/lib/python3.8/site-packages/sqlalchemy/pool/base.py", line 666, in __connect
    pool.logger.debug("Error on connect(): %s", e)
  File "/apps/pkg/anaconda3/2020.11/lib/python3.8/site-packages/sqlalchemy/util/langhelpers.py", line 70, in __exit__
    compat.raise_(
  File "/apps/pkg/anaconda3/2020.11/lib/python3.8/site-packages/sqlalchemy/util/compat.py", line 207, in raise_
    raise exception
  File "/apps/pkg/anaconda3/2020.11/lib/python3.8/site-packages/sqlalchemy/pool/base.py", line 661, in __connect
    self.dbapi_connection = connection = pool._invoke_creator(self)
  File "/apps/pkg/anaconda3/2020.11/lib/python3.8/site-packages/sqlalchemy/engine/create.py", line 590, in connect
    return dialect.connect(*cargs, **cparams)
  File "/apps/pkg/anaconda3/2020.11/lib/python3.8/site-packages/sqlalchemy/engine/default.py", line 597, in connect
    return self.dbapi.connect(*cargs, **cparams)
  File "/users/dwils152/.local/lib/python3.8/site-packages/MySQLdb/__init__.py", line 123, in Connect
    return Connection(*args, **kwargs)
  File "/users/dwils152/.local/lib/python3.8/site-packages/MySQLdb/connections.py", line 185, in __init__
    super().__init__(*args, **kwargs2)
MySQLdb.OperationalError: (2002, "Can't connect to MySQL server on '192.168.170.242' (115)")

The above exception was the direct cause of the following exception:

Traceback (most recent call last):
  File "train.py", line 95, in <module>
    main(args)
  File "train.py", line 69, in main
    study = optuna.create_study(direction="maximize", storage=storage_url)
  File "/users/dwils152/.local/lib/python3.8/site-packages/optuna/_convert_positional_args.py", line 63, in converter_wrapper
    return func(**kwargs)
  File "/users/dwils152/.local/lib/python3.8/site-packages/optuna/study/study.py", line 1147, in create_study
    storage = storages.get_storage(storage)
  File "/users/dwils152/.local/lib/python3.8/site-packages/optuna/storages/__init__.py", line 32, in get_storage
    return _CachedStorage(RDBStorage(storage))
  File "/users/dwils152/.local/lib/python3.8/site-packages/optuna/storages/_rdb/storage.py", line 221, in __init__
    models.BaseModel.metadata.create_all(self.engine)
  File "/apps/pkg/anaconda3/2020.11/lib/python3.8/site-packages/sqlalchemy/sql/schema.py", line 4785, in create_all
    bind._run_ddl_visitor(
  File "/apps/pkg/anaconda3/2020.11/lib/python3.8/site-packages/sqlalchemy/engine/base.py", line 3116, in _run_ddl_visitor
    with self.begin() as conn:
Traceback (most recent call last):
  File "/apps/pkg/anaconda3/2020.11/lib/python3.8/site-packages/sqlalchemy/engine/base.py", line 3250, in _wrap_pool_connect
    return fn()
  File "/apps/pkg/anaconda3/2020.11/lib/python3.8/site-packages/sqlalchemy/pool/base.py", line 310, in connect
    return _ConnectionFairy._checkout(self)
  File "/apps/pkg/anaconda3/2020.11/lib/python3.8/site-packages/sqlalchemy/pool/base.py", line 868, in _checkout
    fairy = _ConnectionRecord.checkout(pool)
  File "/apps/pkg/anaconda3/2020.11/lib/python3.8/site-packages/sqlalchemy/pool/base.py", line 476, in checkout
    rec = pool._do_get()
  File "/apps/pkg/anaconda3/2020.11/lib/python3.8/site-packages/sqlalchemy/pool/impl.py", line 146, in _do_get
    self._dec_overflow()
  File "/apps/pkg/anaconda3/2020.11/lib/python3.8/site-packages/sqlalchemy/util/langhelpers.py", line 70, in __exit__
    compat.raise_(
  File "/apps/pkg/anaconda3/2020.11/lib/python3.8/site-packages/sqlalchemy/util/compat.py", line 207, in raise_
    raise exception
  File "/apps/pkg/anaconda3/2020.11/lib/python3.8/site-packages/sqlalchemy/pool/impl.py", line 143, in _do_get
    return self._create_connection()
  File "/apps/pkg/anaconda3/2020.11/lib/python3.8/site-packages/sqlalchemy/pool/base.py", line 256, in _create_connection
    return _ConnectionRecord(self)
  File "/apps/pkg/anaconda3/2020.11/lib/python3.8/site-packages/sqlalchemy/pool/base.py", line 371, in __init__
    self.__connect()
  File "/apps/pkg/anaconda3/2020.11/lib/python3.8/site-packages/sqlalchemy/pool/base.py", line 666, in __connect
    pool.logger.debug("Error on connect(): %s", e)
  File "/apps/pkg/anaconda3/2020.11/lib/python3.8/site-packages/sqlalchemy/util/langhelpers.py", line 70, in __exit__
    compat.raise_(
  File "/apps/pkg/anaconda3/2020.11/lib/python3.8/site-packages/sqlalchemy/util/compat.py", line 207, in raise_
    raise exception
  File "/apps/pkg/anaconda3/2020.11/lib/python3.8/site-packages/sqlalchemy/pool/base.py", line 661, in __connect
    self.dbapi_connection = connection = pool._invoke_creator(self)
  File "/apps/pkg/anaconda3/2020.11/lib/python3.8/site-packages/sqlalchemy/engine/create.py", line 590, in connect
    return dialect.connect(*cargs, **cparams)
  File "/apps/pkg/anaconda3/2020.11/lib/python3.8/site-packages/sqlalchemy/engine/default.py", line 597, in connect
    return self.dbapi.connect(*cargs, **cparams)
  File "/users/dwils152/.local/lib/python3.8/site-packages/MySQLdb/__init__.py", line 123, in Connect
    return Connection(*args, **kwargs)
  File "/users/dwils152/.local/lib/python3.8/site-packages/MySQLdb/connections.py", line 185, in __init__
    super().__init__(*args, **kwargs2)
MySQLdb.OperationalError: (2002, "Can't connect to MySQL server on '192.168.170.242' (115)")

The above exception was the direct cause of the following exception:

Traceback (most recent call last):
  File "train.py", line 95, in <module>
    main(args)
  File "train.py", line 69, in main
    study = optuna.create_study(direction="maximize", storage=storage_url)
  File "/users/dwils152/.local/lib/python3.8/site-packages/optuna/_convert_positional_args.py", line 63, in converter_wrapper
    return func(**kwargs)
  File "/users/dwils152/.local/lib/python3.8/site-packages/optuna/study/study.py", line 1147, in create_study
    storage = storages.get_storage(storage)
  File "/users/dwils152/.local/lib/python3.8/site-packages/optuna/storages/__init__.py", line 32, in get_storage
    return _CachedStorage(RDBStorage(storage))
  File "/users/dwils152/.local/lib/python3.8/site-packages/optuna/storages/_rdb/storage.py", line 221, in __init__
    models.BaseModel.metadata.create_all(self.engine)
  File "/apps/pkg/anaconda3/2020.11/lib/python3.8/site-packages/sqlalchemy/sql/schema.py", line 4785, in create_all
    bind._run_ddl_visitor(
  File "/apps/pkg/anaconda3/2020.11/lib/python3.8/site-packages/sqlalchemy/engine/base.py", line 3116, in _run_ddl_visitor
    with self.begin() as conn:
Traceback (most recent call last):
  File "/apps/pkg/anaconda3/2020.11/lib/python3.8/site-packages/sqlalchemy/engine/base.py", line 3250, in _wrap_pool_connect
    return fn()
  File "/apps/pkg/anaconda3/2020.11/lib/python3.8/site-packages/sqlalchemy/pool/base.py", line 310, in connect
    return _ConnectionFairy._checkout(self)
  File "/apps/pkg/anaconda3/2020.11/lib/python3.8/site-packages/sqlalchemy/pool/base.py", line 868, in _checkout
    fairy = _ConnectionRecord.checkout(pool)
  File "/apps/pkg/anaconda3/2020.11/lib/python3.8/site-packages/sqlalchemy/pool/base.py", line 476, in checkout
    rec = pool._do_get()
  File "/apps/pkg/anaconda3/2020.11/lib/python3.8/site-packages/sqlalchemy/pool/impl.py", line 146, in _do_get
    self._dec_overflow()
  File "/apps/pkg/anaconda3/2020.11/lib/python3.8/site-packages/sqlalchemy/util/langhelpers.py", line 70, in __exit__
    compat.raise_(
  File "/apps/pkg/anaconda3/2020.11/lib/python3.8/site-packages/sqlalchemy/util/compat.py", line 207, in raise_
    raise exception
  File "/apps/pkg/anaconda3/2020.11/lib/python3.8/site-packages/sqlalchemy/pool/impl.py", line 143, in _do_get
    return self._create_connection()
  File "/apps/pkg/anaconda3/2020.11/lib/python3.8/site-packages/sqlalchemy/pool/base.py", line 256, in _create_connection
    return _ConnectionRecord(self)
  File "/apps/pkg/anaconda3/2020.11/lib/python3.8/site-packages/sqlalchemy/pool/base.py", line 371, in __init__
    self.__connect()
  File "/apps/pkg/anaconda3/2020.11/lib/python3.8/site-packages/sqlalchemy/pool/base.py", line 666, in __connect
    pool.logger.debug("Error on connect(): %s", e)
  File "/apps/pkg/anaconda3/2020.11/lib/python3.8/site-packages/sqlalchemy/util/langhelpers.py", line 70, in __exit__
    compat.raise_(
  File "/apps/pkg/anaconda3/2020.11/lib/python3.8/site-packages/sqlalchemy/util/compat.py", line 207, in raise_
    raise exception
  File "/apps/pkg/anaconda3/2020.11/lib/python3.8/site-packages/sqlalchemy/pool/base.py", line 661, in __connect
    self.dbapi_connection = connection = pool._invoke_creator(self)
  File "/apps/pkg/anaconda3/2020.11/lib/python3.8/site-packages/sqlalchemy/engine/create.py", line 590, in connect
    return dialect.connect(*cargs, **cparams)
  File "/apps/pkg/anaconda3/2020.11/lib/python3.8/site-packages/sqlalchemy/engine/default.py", line 597, in connect
    return self.dbapi.connect(*cargs, **cparams)
  File "/users/dwils152/.local/lib/python3.8/site-packages/MySQLdb/__init__.py", line 123, in Connect
    return Connection(*args, **kwargs)
  File "/users/dwils152/.local/lib/python3.8/site-packages/MySQLdb/connections.py", line 185, in __init__
    super().__init__(*args, **kwargs2)
MySQLdb.OperationalError: (2002, "Can't connect to MySQL server on '192.168.170.242' (115)")

The above exception was the direct cause of the following exception:

Traceback (most recent call last):
  File "train.py", line 95, in <module>
    main(args)
  File "train.py", line 69, in main
    study = optuna.create_study(direction="maximize", storage=storage_url)
  File "/users/dwils152/.local/lib/python3.8/site-packages/optuna/_convert_positional_args.py", line 63, in converter_wrapper
    return func(**kwargs)
  File "/users/dwils152/.local/lib/python3.8/site-packages/optuna/study/study.py", line 1147, in create_study
    storage = storages.get_storage(storage)
  File "/users/dwils152/.local/lib/python3.8/site-packages/optuna/storages/__init__.py", line 32, in get_storage
    return _CachedStorage(RDBStorage(storage))
  File "/users/dwils152/.local/lib/python3.8/site-packages/optuna/storages/_rdb/storage.py", line 221, in __init__
    models.BaseModel.metadata.create_all(self.engine)
  File "/apps/pkg/anaconda3/2020.11/lib/python3.8/site-packages/sqlalchemy/sql/schema.py", line 4785, in create_all
    bind._run_ddl_visitor(
  File "/apps/pkg/anaconda3/2020.11/lib/python3.8/site-packages/sqlalchemy/engine/base.py", line 3116, in _run_ddl_visitor
    with self.begin() as conn:
  File "/apps/pkg/anaconda3/2020.11/lib/python3.8/site-packages/sqlalchemy/engine/base.py", line 3032, in begin
    conn = self.connect(close_with_result=close_with_result)
  File "/apps/pkg/anaconda3/2020.11/lib/python3.8/site-packages/sqlalchemy/engine/base.py", line 3204, in connect
    return self._connection_cls(self, close_with_result=close_with_result)
  File "/apps/pkg/anaconda3/2020.11/lib/python3.8/site-packages/sqlalchemy/engine/base.py", line 96, in __init__
    else engine.raw_connection()
  File "/apps/pkg/anaconda3/2020.11/lib/python3.8/site-packages/sqlalchemy/engine/base.py", line 3283, in raw_connection
    return self._wrap_pool_connect(self.pool.connect, _connection)
  File "/apps/pkg/anaconda3/2020.11/lib/python3.8/site-packages/sqlalchemy/engine/base.py", line 3253, in _wrap_pool_connect
    Connection._handle_dbapi_exception_noconnection(
  File "/apps/pkg/anaconda3/2020.11/lib/python3.8/site-packages/sqlalchemy/engine/base.py", line 2100, in _handle_dbapi_exception_noconnection
    util.raise_(
  File "/apps/pkg/anaconda3/2020.11/lib/python3.8/site-packages/sqlalchemy/util/compat.py", line 207, in raise_
    raise exception
  File "/apps/pkg/anaconda3/2020.11/lib/python3.8/site-packages/sqlalchemy/engine/base.py", line 3250, in _wrap_pool_connect
    return fn()
  File "/apps/pkg/anaconda3/2020.11/lib/python3.8/site-packages/sqlalchemy/pool/base.py", line 310, in connect
    return _ConnectionFairy._checkout(self)
  File "/apps/pkg/anaconda3/2020.11/lib/python3.8/site-packages/sqlalchemy/pool/base.py", line 868, in _checkout
    fairy = _ConnectionRecord.checkout(pool)
  File "/apps/pkg/anaconda3/2020.11/lib/python3.8/site-packages/sqlalchemy/pool/base.py", line 476, in checkout
    rec = pool._do_get()
  File "/apps/pkg/anaconda3/2020.11/lib/python3.8/site-packages/sqlalchemy/pool/impl.py", line 146, in _do_get
    self._dec_overflow()
  File "/apps/pkg/anaconda3/2020.11/lib/python3.8/site-packages/sqlalchemy/util/langhelpers.py", line 70, in __exit__
    compat.raise_(
  File "/apps/pkg/anaconda3/2020.11/lib/python3.8/site-packages/sqlalchemy/util/compat.py", line 207, in raise_
    raise exception
  File "/apps/pkg/anaconda3/2020.11/lib/python3.8/site-packages/sqlalchemy/pool/impl.py", line 143, in _do_get
    return self._create_connection()
  File "/apps/pkg/anaconda3/2020.11/lib/python3.8/site-packages/sqlalchemy/pool/base.py", line 256, in _create_connection
    return _ConnectionRecord(self)
  File "/apps/pkg/anaconda3/2020.11/lib/python3.8/site-packages/sqlalchemy/pool/base.py", line 371, in __init__
    self.__connect()
  File "/apps/pkg/anaconda3/2020.11/lib/python3.8/site-packages/sqlalchemy/pool/base.py", line 666, in __connect
    pool.logger.debug("Error on connect(): %s", e)
  File "/apps/pkg/anaconda3/2020.11/lib/python3.8/site-packages/sqlalchemy/util/langhelpers.py", line 70, in __exit__
    compat.raise_(
  File "/apps/pkg/anaconda3/2020.11/lib/python3.8/site-packages/sqlalchemy/util/compat.py", line 207, in raise_
    raise exception
  File "/apps/pkg/anaconda3/2020.11/lib/python3.8/site-packages/sqlalchemy/pool/base.py", line 661, in __connect
    self.dbapi_connection = connection = pool._invoke_creator(self)
  File "/apps/pkg/anaconda3/2020.11/lib/python3.8/site-packages/sqlalchemy/engine/create.py", line 590, in connect
    return dialect.connect(*cargs, **cparams)
  File "/apps/pkg/anaconda3/2020.11/lib/python3.8/site-packages/sqlalchemy/engine/default.py", line 597, in connect
    return self.dbapi.connect(*cargs, **cparams)
  File "/users/dwils152/.local/lib/python3.8/site-packages/MySQLdb/__init__.py", line 123, in Connect
    return Connection(*args, **kwargs)
  File "/users/dwils152/.local/lib/python3.8/site-packages/MySQLdb/connections.py", line 185, in __init__
    super().__init__(*args, **kwargs2)
sqlalchemy.exc.OperationalError: (MySQLdb.OperationalError) (2002, "Can't connect to MySQL server on '192.168.170.242' (115)")
(Background on this error at: https://sqlalche.me/e/14/e3q8)
  File "/apps/pkg/anaconda3/2020.11/lib/python3.8/site-packages/sqlalchemy/engine/base.py", line 3032, in begin
    conn = self.connect(close_with_result=close_with_result)
  File "/apps/pkg/anaconda3/2020.11/lib/python3.8/site-packages/sqlalchemy/engine/base.py", line 3204, in connect
    return self._connection_cls(self, close_with_result=close_with_result)
  File "/apps/pkg/anaconda3/2020.11/lib/python3.8/site-packages/sqlalchemy/engine/base.py", line 96, in __init__
    else engine.raw_connection()
  File "/apps/pkg/anaconda3/2020.11/lib/python3.8/site-packages/sqlalchemy/engine/base.py", line 3283, in raw_connection
    return self._wrap_pool_connect(self.pool.connect, _connection)
  File "/apps/pkg/anaconda3/2020.11/lib/python3.8/site-packages/sqlalchemy/engine/base.py", line 3253, in _wrap_pool_connect
    Connection._handle_dbapi_exception_noconnection(
  File "/apps/pkg/anaconda3/2020.11/lib/python3.8/site-packages/sqlalchemy/engine/base.py", line 2100, in _handle_dbapi_exception_noconnection
    util.raise_(
  File "/apps/pkg/anaconda3/2020.11/lib/python3.8/site-packages/sqlalchemy/util/compat.py", line 207, in raise_
    raise exception
  File "/apps/pkg/anaconda3/2020.11/lib/python3.8/site-packages/sqlalchemy/engine/base.py", line 3250, in _wrap_pool_connect
    return fn()
  File "/apps/pkg/anaconda3/2020.11/lib/python3.8/site-packages/sqlalchemy/pool/base.py", line 310, in connect
    return _ConnectionFairy._checkout(self)
  File "/apps/pkg/anaconda3/2020.11/lib/python3.8/site-packages/sqlalchemy/pool/base.py", line 868, in _checkout
    fairy = _ConnectionRecord.checkout(pool)
  File "/apps/pkg/anaconda3/2020.11/lib/python3.8/site-packages/sqlalchemy/pool/base.py", line 476, in checkout
    rec = pool._do_get()
  File "/apps/pkg/anaconda3/2020.11/lib/python3.8/site-packages/sqlalchemy/pool/impl.py", line 146, in _do_get
    self._dec_overflow()
  File "/apps/pkg/anaconda3/2020.11/lib/python3.8/site-packages/sqlalchemy/util/langhelpers.py", line 70, in __exit__
    compat.raise_(
  File "/apps/pkg/anaconda3/2020.11/lib/python3.8/site-packages/sqlalchemy/util/compat.py", line 207, in raise_
    raise exception
  File "/apps/pkg/anaconda3/2020.11/lib/python3.8/site-packages/sqlalchemy/pool/impl.py", line 143, in _do_get
    return self._create_connection()
  File "/apps/pkg/anaconda3/2020.11/lib/python3.8/site-packages/sqlalchemy/pool/base.py", line 256, in _create_connection
    return _ConnectionRecord(self)
  File "/apps/pkg/anaconda3/2020.11/lib/python3.8/site-packages/sqlalchemy/pool/base.py", line 371, in __init__
    self.__connect()
  File "/apps/pkg/anaconda3/2020.11/lib/python3.8/site-packages/sqlalchemy/pool/base.py", line 666, in __connect
    pool.logger.debug("Error on connect(): %s", e)
  File "/apps/pkg/anaconda3/2020.11/lib/python3.8/site-packages/sqlalchemy/util/langhelpers.py", line 70, in __exit__
    compat.raise_(
  File "/apps/pkg/anaconda3/2020.11/lib/python3.8/site-packages/sqlalchemy/util/compat.py", line 207, in raise_
    raise exception
  File "/apps/pkg/anaconda3/2020.11/lib/python3.8/site-packages/sqlalchemy/pool/base.py", line 661, in __connect
    self.dbapi_connection = connection = pool._invoke_creator(self)
  File "/apps/pkg/anaconda3/2020.11/lib/python3.8/site-packages/sqlalchemy/engine/create.py", line 590, in connect
    return dialect.connect(*cargs, **cparams)
  File "/apps/pkg/anaconda3/2020.11/lib/python3.8/site-packages/sqlalchemy/engine/default.py", line 597, in connect
    return self.dbapi.connect(*cargs, **cparams)
  File "/users/dwils152/.local/lib/python3.8/site-packages/MySQLdb/__init__.py", line 123, in Connect
    return Connection(*args, **kwargs)
  File "/users/dwils152/.local/lib/python3.8/site-packages/MySQLdb/connections.py", line 185, in __init__
    super().__init__(*args, **kwargs2)
sqlalchemy.exc.OperationalError: (MySQLdb.OperationalError) (2002, "Can't connect to MySQL server on '192.168.170.242' (115)")
(Background on this error at: https://sqlalche.me/e/14/e3q8)
  File "/apps/pkg/anaconda3/2020.11/lib/python3.8/site-packages/sqlalchemy/engine/base.py", line 3032, in begin
    conn = self.connect(close_with_result=close_with_result)
  File "/apps/pkg/anaconda3/2020.11/lib/python3.8/site-packages/sqlalchemy/engine/base.py", line 3204, in connect
    return self._connection_cls(self, close_with_result=close_with_result)
  File "/apps/pkg/anaconda3/2020.11/lib/python3.8/site-packages/sqlalchemy/engine/base.py", line 96, in __init__
    else engine.raw_connection()
  File "/apps/pkg/anaconda3/2020.11/lib/python3.8/site-packages/sqlalchemy/engine/base.py", line 3283, in raw_connection
    return self._wrap_pool_connect(self.pool.connect, _connection)
  File "/apps/pkg/anaconda3/2020.11/lib/python3.8/site-packages/sqlalchemy/engine/base.py", line 3253, in _wrap_pool_connect
    Connection._handle_dbapi_exception_noconnection(
  File "/apps/pkg/anaconda3/2020.11/lib/python3.8/site-packages/sqlalchemy/engine/base.py", line 2100, in _handle_dbapi_exception_noconnection
    util.raise_(
  File "/apps/pkg/anaconda3/2020.11/lib/python3.8/site-packages/sqlalchemy/util/compat.py", line 207, in raise_
    raise exception
  File "/apps/pkg/anaconda3/2020.11/lib/python3.8/site-packages/sqlalchemy/engine/base.py", line 3250, in _wrap_pool_connect
    return fn()
  File "/apps/pkg/anaconda3/2020.11/lib/python3.8/site-packages/sqlalchemy/pool/base.py", line 310, in connect
    return _ConnectionFairy._checkout(self)
  File "/apps/pkg/anaconda3/2020.11/lib/python3.8/site-packages/sqlalchemy/pool/base.py", line 868, in _checkout
    fairy = _ConnectionRecord.checkout(pool)
  File "/apps/pkg/anaconda3/2020.11/lib/python3.8/site-packages/sqlalchemy/pool/base.py", line 476, in checkout
    rec = pool._do_get()
  File "/apps/pkg/anaconda3/2020.11/lib/python3.8/site-packages/sqlalchemy/pool/impl.py", line 146, in _do_get
    self._dec_overflow()
  File "/apps/pkg/anaconda3/2020.11/lib/python3.8/site-packages/sqlalchemy/util/langhelpers.py", line 70, in __exit__
    compat.raise_(
  File "/apps/pkg/anaconda3/2020.11/lib/python3.8/site-packages/sqlalchemy/util/compat.py", line 207, in raise_
    raise exception
  File "/apps/pkg/anaconda3/2020.11/lib/python3.8/site-packages/sqlalchemy/pool/impl.py", line 143, in _do_get
    return self._create_connection()
  File "/apps/pkg/anaconda3/2020.11/lib/python3.8/site-packages/sqlalchemy/pool/base.py", line 256, in _create_connection
    return _ConnectionRecord(self)
  File "/apps/pkg/anaconda3/2020.11/lib/python3.8/site-packages/sqlalchemy/pool/base.py", line 371, in __init__
    self.__connect()
  File "/apps/pkg/anaconda3/2020.11/lib/python3.8/site-packages/sqlalchemy/pool/base.py", line 666, in __connect
    pool.logger.debug("Error on connect(): %s", e)
  File "/apps/pkg/anaconda3/2020.11/lib/python3.8/site-packages/sqlalchemy/util/langhelpers.py", line 70, in __exit__
    compat.raise_(
  File "/apps/pkg/anaconda3/2020.11/lib/python3.8/site-packages/sqlalchemy/util/compat.py", line 207, in raise_
    raise exception
  File "/apps/pkg/anaconda3/2020.11/lib/python3.8/site-packages/sqlalchemy/pool/base.py", line 661, in __connect
    self.dbapi_connection = connection = pool._invoke_creator(self)
  File "/apps/pkg/anaconda3/2020.11/lib/python3.8/site-packages/sqlalchemy/engine/create.py", line 590, in connect
    return dialect.connect(*cargs, **cparams)
  File "/apps/pkg/anaconda3/2020.11/lib/python3.8/site-packages/sqlalchemy/engine/default.py", line 597, in connect
    return self.dbapi.connect(*cargs, **cparams)
  File "/users/dwils152/.local/lib/python3.8/site-packages/MySQLdb/__init__.py", line 123, in Connect
    return Connection(*args, **kwargs)
  File "/users/dwils152/.local/lib/python3.8/site-packages/MySQLdb/connections.py", line 185, in __init__
    super().__init__(*args, **kwargs2)
sqlalchemy.exc.OperationalError: (MySQLdb.OperationalError) (2002, "Can't connect to MySQL server on '192.168.170.242' (115)")
(Background on this error at: https://sqlalche.me/e/14/e3q8)
Traceback (most recent call last):
  File "/apps/pkg/anaconda3/2020.11/lib/python3.8/site-packages/sqlalchemy/engine/base.py", line 3250, in _wrap_pool_connect
    return fn()
  File "/apps/pkg/anaconda3/2020.11/lib/python3.8/site-packages/sqlalchemy/pool/base.py", line 310, in connect
    return _ConnectionFairy._checkout(self)
  File "/apps/pkg/anaconda3/2020.11/lib/python3.8/site-packages/sqlalchemy/pool/base.py", line 868, in _checkout
    fairy = _ConnectionRecord.checkout(pool)
  File "/apps/pkg/anaconda3/2020.11/lib/python3.8/site-packages/sqlalchemy/pool/base.py", line 476, in checkout
    rec = pool._do_get()
  File "/apps/pkg/anaconda3/2020.11/lib/python3.8/site-packages/sqlalchemy/pool/impl.py", line 146, in _do_get
    self._dec_overflow()
  File "/apps/pkg/anaconda3/2020.11/lib/python3.8/site-packages/sqlalchemy/util/langhelpers.py", line 70, in __exit__
    compat.raise_(
  File "/apps/pkg/anaconda3/2020.11/lib/python3.8/site-packages/sqlalchemy/util/compat.py", line 207, in raise_
    raise exception
  File "/apps/pkg/anaconda3/2020.11/lib/python3.8/site-packages/sqlalchemy/pool/impl.py", line 143, in _do_get
    return self._create_connection()
  File "/apps/pkg/anaconda3/2020.11/lib/python3.8/site-packages/sqlalchemy/pool/base.py", line 256, in _create_connection
    return _ConnectionRecord(self)
  File "/apps/pkg/anaconda3/2020.11/lib/python3.8/site-packages/sqlalchemy/pool/base.py", line 371, in __init__
    self.__connect()
  File "/apps/pkg/anaconda3/2020.11/lib/python3.8/site-packages/sqlalchemy/pool/base.py", line 666, in __connect
    pool.logger.debug("Error on connect(): %s", e)
  File "/apps/pkg/anaconda3/2020.11/lib/python3.8/site-packages/sqlalchemy/util/langhelpers.py", line 70, in __exit__
    compat.raise_(
  File "/apps/pkg/anaconda3/2020.11/lib/python3.8/site-packages/sqlalchemy/util/compat.py", line 207, in raise_
    raise exception
  File "/apps/pkg/anaconda3/2020.11/lib/python3.8/site-packages/sqlalchemy/pool/base.py", line 661, in __connect
    self.dbapi_connection = connection = pool._invoke_creator(self)
  File "/apps/pkg/anaconda3/2020.11/lib/python3.8/site-packages/sqlalchemy/engine/create.py", line 590, in connect
    return dialect.connect(*cargs, **cparams)
  File "/apps/pkg/anaconda3/2020.11/lib/python3.8/site-packages/sqlalchemy/engine/default.py", line 597, in connect
    return self.dbapi.connect(*cargs, **cparams)
  File "/users/dwils152/.local/lib/python3.8/site-packages/MySQLdb/__init__.py", line 123, in Connect
    return Connection(*args, **kwargs)
  File "/users/dwils152/.local/lib/python3.8/site-packages/MySQLdb/connections.py", line 185, in __init__
    super().__init__(*args, **kwargs2)
MySQLdb.OperationalError: (2002, "Can't connect to MySQL server on '192.168.170.242' (115)")

The above exception was the direct cause of the following exception:

Traceback (most recent call last):
  File "train.py", line 95, in <module>
    main(args)
  File "train.py", line 69, in main
    study = optuna.create_study(direction="maximize", storage=storage_url)
  File "/users/dwils152/.local/lib/python3.8/site-packages/optuna/_convert_positional_args.py", line 63, in converter_wrapper
    return func(**kwargs)
  File "/users/dwils152/.local/lib/python3.8/site-packages/optuna/study/study.py", line 1147, in create_study
    storage = storages.get_storage(storage)
  File "/users/dwils152/.local/lib/python3.8/site-packages/optuna/storages/__init__.py", line 32, in get_storage
    return _CachedStorage(RDBStorage(storage))
  File "/users/dwils152/.local/lib/python3.8/site-packages/optuna/storages/_rdb/storage.py", line 221, in __init__
    models.BaseModel.metadata.create_all(self.engine)
  File "/apps/pkg/anaconda3/2020.11/lib/python3.8/site-packages/sqlalchemy/sql/schema.py", line 4785, in create_all
    bind._run_ddl_visitor(
  File "/apps/pkg/anaconda3/2020.11/lib/python3.8/site-packages/sqlalchemy/engine/base.py", line 3116, in _run_ddl_visitor
    with self.begin() as conn:
  File "/apps/pkg/anaconda3/2020.11/lib/python3.8/site-packages/sqlalchemy/engine/base.py", line 3032, in begin
    conn = self.connect(close_with_result=close_with_result)
  File "/apps/pkg/anaconda3/2020.11/lib/python3.8/site-packages/sqlalchemy/engine/base.py", line 3204, in connect
    return self._connection_cls(self, close_with_result=close_with_result)
  File "/apps/pkg/anaconda3/2020.11/lib/python3.8/site-packages/sqlalchemy/engine/base.py", line 96, in __init__
    else engine.raw_connection()
  File "/apps/pkg/anaconda3/2020.11/lib/python3.8/site-packages/sqlalchemy/engine/base.py", line 3283, in raw_connection
    return self._wrap_pool_connect(self.pool.connect, _connection)
  File "/apps/pkg/anaconda3/2020.11/lib/python3.8/site-packages/sqlalchemy/engine/base.py", line 3253, in _wrap_pool_connect
    Connection._handle_dbapi_exception_noconnection(
  File "/apps/pkg/anaconda3/2020.11/lib/python3.8/site-packages/sqlalchemy/engine/base.py", line 2100, in _handle_dbapi_exception_noconnection
    util.raise_(
  File "/apps/pkg/anaconda3/2020.11/lib/python3.8/site-packages/sqlalchemy/util/compat.py", line 207, in raise_
    raise exception
  File "/apps/pkg/anaconda3/2020.11/lib/python3.8/site-packages/sqlalchemy/engine/base.py", line 3250, in _wrap_pool_connect
    return fn()
  File "/apps/pkg/anaconda3/2020.11/lib/python3.8/site-packages/sqlalchemy/pool/base.py", line 310, in connect
    return _ConnectionFairy._checkout(self)
  File "/apps/pkg/anaconda3/2020.11/lib/python3.8/site-packages/sqlalchemy/pool/base.py", line 868, in _checkout
    fairy = _ConnectionRecord.checkout(pool)
  File "/apps/pkg/anaconda3/2020.11/lib/python3.8/site-packages/sqlalchemy/pool/base.py", line 476, in checkout
    rec = pool._do_get()
  File "/apps/pkg/anaconda3/2020.11/lib/python3.8/site-packages/sqlalchemy/pool/impl.py", line 146, in _do_get
    self._dec_overflow()
  File "/apps/pkg/anaconda3/2020.11/lib/python3.8/site-packages/sqlalchemy/util/langhelpers.py", line 70, in __exit__
    compat.raise_(
  File "/apps/pkg/anaconda3/2020.11/lib/python3.8/site-packages/sqlalchemy/util/compat.py", line 207, in raise_
    raise exception
  File "/apps/pkg/anaconda3/2020.11/lib/python3.8/site-packages/sqlalchemy/pool/impl.py", line 143, in _do_get
    return self._create_connection()
  File "/apps/pkg/anaconda3/2020.11/lib/python3.8/site-packages/sqlalchemy/pool/base.py", line 256, in _create_connection
    return _ConnectionRecord(self)
  File "/apps/pkg/anaconda3/2020.11/lib/python3.8/site-packages/sqlalchemy/pool/base.py", line 371, in __init__
    self.__connect()
  File "/apps/pkg/anaconda3/2020.11/lib/python3.8/site-packages/sqlalchemy/pool/base.py", line 666, in __connect
    pool.logger.debug("Error on connect(): %s", e)
  File "/apps/pkg/anaconda3/2020.11/lib/python3.8/site-packages/sqlalchemy/util/langhelpers.py", line 70, in __exit__
    compat.raise_(
  File "/apps/pkg/anaconda3/2020.11/lib/python3.8/site-packages/sqlalchemy/util/compat.py", line 207, in raise_
    raise exception
  File "/apps/pkg/anaconda3/2020.11/lib/python3.8/site-packages/sqlalchemy/pool/base.py", line 661, in __connect
    self.dbapi_connection = connection = pool._invoke_creator(self)
  File "/apps/pkg/anaconda3/2020.11/lib/python3.8/site-packages/sqlalchemy/engine/create.py", line 590, in connect
    return dialect.connect(*cargs, **cparams)
  File "/apps/pkg/anaconda3/2020.11/lib/python3.8/site-packages/sqlalchemy/engine/default.py", line 597, in connect
    return self.dbapi.connect(*cargs, **cparams)
  File "/users/dwils152/.local/lib/python3.8/site-packages/MySQLdb/__init__.py", line 123, in Connect
    return Connection(*args, **kwargs)
  File "/users/dwils152/.local/lib/python3.8/site-packages/MySQLdb/connections.py", line 185, in __init__
    super().__init__(*args, **kwargs2)
sqlalchemy.exc.OperationalError: (MySQLdb.OperationalError) (2002, "Can't connect to MySQL server on '192.168.170.242' (115)")
(Background on this error at: https://sqlalche.me/e/14/e3q8)
srun: error: str-gpu3: tasks 0-3: Exited with exit code 1
srun: launch/slurm: _step_signal: Terminating StepId=6134175.0
